Workbook

Sheet 精算データ
B1: 楊 | C1: 張 | D1: 菜 | E1: 閻 | F1: 朱 | G1: 黄
A2: 合計 | B2: =SUM(B3:B930) -> 0 | C2: =SUM(C3:C930) -> 0.1 | D2: =SUM(D3:D930) -> 106.4 | E2: =SUM(E3:E930) -> -301 | F2: =SUM(F3:F930) -> 231.3 | G2: =SUM(G3:G930) -> 21.3
A3: その他 | B3: =15+32-10-57 -> -20 | C3: =11.5-19-22-90 -> -119.5 | E3: 3500
A4: 42736
A5: 42736
A6: 42737
A7: 42738
A8: 42739
A9: 42740
A10: 42741
A11: 42742
A12: 42743
A13: 42744
A14: 42745
A15: 42746
... A26: 42757
A27: 42758 | B27: 12 | C27: 13
A28: 42759 | C28: -26
A29: 42760 | B29: 8 | C29: 14
A30: 42761 | C30: -186
A31: 42762
A32: 42763
A33: 42764
A34: 42765
A35: 42766
A36: 42767 | C36: 14
A37: 42768 | B37: =8-8 -> 0 | D37: =8-8 -> 0
A38: 42769
A39: 42770
A40: 42771 | C40: =-44+100 -> 56
A41: 42772
A42: 42773 | B42: 8 | C42: -17 | D42: 8
A43: 42774 | B43: 8 | C43: -33 | D43: 8
A44: 42775
A45: 42776
A46: 42777
A47: 42778
A48: 42779
A49: 42780
A50: 42781
...

Sheet 202012
C1: 楊 | F1: 張 | I1: 菜 | L1: 閻 | O1: 朱 | R1: 黄
A2: 日付 | B2: 曜日 | C2: =SUM(D3:D33) -> 0 | F2: =SUM(G:G) -> 0 | I2: =SUM(J:J) -> 0 | L2: =SUM(M:M) -> 0 | O2: =SUM(P:P) -> 5 | R2: =SUM(S:S) -> 0
A3: 44166 | B3: 火
A4: 44167 | B4: 水
A5: 44168 | B5: 木 | O5: KFC | P5: 5
A6: 44169 | B6: 金
A7: 44170 | B7: 土
A8: 44171 | B8: 日
A9: 44172 | B9: 月
A10: 44173 | B10: 火
A11: 44174 | B11: 水
A12: 44175 | B12: 木
A13: 44176 | B13: 金
A14: 44177 | B14: 土
A15: 44178 | B15: 日
A16: 44179 | B16: 月
A17: 44180 | B17: 火
... A33: 44196 | B33: 木

Sheet 202011
C1: 楊 | F1: 張 | I1: 菜 | L1: 閻 | O1: 朱 | R1: 黄
A2: 日付 | B2: 曜日 | C2: =SUM(D3:D33) -> 0 | F2: =SUM(G:G) -> 0 | I2: =SUM(J:J) -> 24.9 | L2: =SUM(M:M) -> -48 | O2: =SUM(P:P) -> 111 | R2: =SUM(S:S) -> 0
A3: 44136 | B3: 日
A4: 44137 | B4: 月
A5: 44138 | B5: 火 | O5: KFC | P5: 5
A6: 44139 | B6: 水 | L6: 精算 | M6: -4 | O6: スターバックス | P6: 24
A7: 44140 | B7: 木 | O7: KFC | P7: 5
A8: 44141 | B8: 金 | O8: KFC | P8: 5
A9: 44142 | B9: 土
A10: 44143 | B10: 日
A11: 44144 | B11: 月 | O11: KFC | P11: 5
A12: 44145 | B12: 火 | O12: KFC | P12: 5
A13: 44146 | B13: 水 | I13: KFC | J13: 10 | O13: KFC | P13: -5
O14: スターバックス | P14: 22
A15: 44147 | B15: 木 | I15: KFC | J15: 9.9
A16: 44148 | B16: 金 | L16: スターバックス | M16: -22
A17: 44149 | B17: 土
A18: 44150 | B18: 日
A19: 44151 | B19: 月 | O19: KFC | P19: 5
A20: 44152 | B20: 火 | O20: KFC | P20: 5
A21: 44153 | B21: 水
A22: 44154 | B22: 木 | O22: KFC | P22: 5
A23: 44155 | B23: 金 | L23: スターバックス | M23: -22
A24: 44156 | B24: 土
A25: 44157 | B25: 日
A26: 44158 | B26: 月 | I26: KFC | J26: 5 | O26: KFC | P26: 5
A27: 44159 | B27: 火 | O27: KFC | P27: 5
A28: 44160 | B28: 水 | O28: KFC | P28: 5
A29: 44161 | B29: 木 | O29: KFC | P29: 5
A30: 44162 | B30: 金 | O30: KFC | P30: 5
A31: 44163 | B31: 土
A32: 44164 | B32: 日
A33: 44165 | B33: 月 | O33: KFC | P33: 5

Sheet 202010
C1: 楊 | F1: 張 | I1: 菜 | L1: 閻 | O1: 朱 | R1: 黄
A2: 日付 | B2: 曜日 | C2: =SUM(D3:D36) -> 0 | F2: =SUM(G:G) -> 0 | I2: =SUM(J:J) -> 31.5 | L2: =SUM(M:M) -> -20 | O2: =SUM(P:P) -> 77.7 | R2: =SUM(S:S) -> 0
A3: 44105 | B3: 木
A4: 44106 | B4: 金
A5: 44107 | B5: 土
A6: 44108 | B6: 日
A7: 44109 | B7: 月
A8: 44110 | B8: 火
A9: 44111 | B9: 水 | O9: KFC | P9: 6.9
O10: KFC | P10: -5
A11: 44112 | B11: 木 | O11: KFC | P11: 6.9
O12: KFC | P12: -5
A13: 44113 | B13: 金 | O13: KFC | P13: 6.9
O14: KFC | P14: -5
A15: 44114 | B15: 土
A16: 44115 | B16: 日
A17: 44116 | B17: 月 | O17: ファミリー | P17: 9.5
O18: KFC | P18: -5
A19: 44117 | B19: 火 | O19: KFC | P19: 5
A20: 44118 | B20: 水
A21: 44119 | B21: 木 | O21: KFC | P21: 10
A22: 44120 | B22: 金
A23: 44121 | B23: 土
A24: 44122 | B24: 日
A25: 44123 | B25: 月
A26: 44124 | B26: 火 | I26: KFC | J26: 21.5 | O26: KFC | P26: 12.5
A27: 44125 | B27: 水 | L27: スターバックス | M27: -20 | O27: スターバックス | P27: 20
A28: 44126 | B28: 木 | I28: KFC | J28: 10 | O28: KFC | P28: 10
A29: 44127 | B29: 金
A30: 44128 | B30: 土
A31: 44129 | B31: 日
A32: 44130 | B32: 月 | O32: KFC | P32: 5
A33: 44131 | B33: 火 | O33: KFC | P33: 5
A34: 44132 | B34: 水
A35: 44133 | B35: 木
A36: 44134 | B36: 金
A37: 44135 | B37: 土

Sheet 202009
C1: 楊 | F1: 張 | I1: 菜 | L1: 閻 | O1: 朱 | R1: 黄
A2: 日付 | B2: 曜日 | C2: =SUM(D3:D32) -> 0 | F2: =SUM(G:G) -> -83 | I2: =SUM(J:J) -> 32 | L2: =SUM(M:M) -> 0 | O2: =SUM(P:P) -> 21 | R2: =SUM(S:S) -> 0
A3: 44075 | B3: 火 | O3: KFC | P3: -5
A4: 44076 | B4: 水 | O4: スターバックス | P4: 22
A5: 44077 | B5: 木 | O5: KFC | P5: -5
A6: 44078 | B6: 金 | O6: KFC | P6: -5
A7: 44079 | B7: 土
A8: 44080 | B8: 日
A9: 44081 | B9: 月
A10: 44082 | B10: 火 | O10: KFC | P10: -5
A11: 44083 | B11: 水 | F11: スターバックス | G11: 84
A12: 44084 | B12: 木 | O12: KFC | P12: -10
A13: 44085 | B13: 金 | G13: . | O13: KFC | P13: -5
A14: 44086 | B14: 土
A15: 44087 | B15: 日
A16: 44088 | B16: 月 | O16: スターバックス | P16: 22
A17: 44089 | B17: 火 | O17: KFC | P17: -5
A18: 44090 | B18: 水
A19: 44091 | B19: 木
A20: 44092 | B20: 金 | O20: KFC | P20: -5
A21: 44093 | B21: 土
A22: 44094 | B22: 日
A23: 44095 | B23: 月 | O23: KFC | P23: -5
A24: 44096 | B24: 火 | I24: スターバックス | J24: 22
A25: 44097 | B25: 水 | F25: 精算 | G25: -167 | O25: KFC | P25: -5
A26: 44098 | B26: 木 | O26: KFC | P26: -5
A27: 44099 | B27: 金 | O27: スターバックス | P27: 22
A28: 44100 | B28: 土
A29: 44101 | B29: 日
A30: 44102 | B30: 月 | O30: スターバックス | P30: 20
A31: 44103 | B31: 火 | O31: KFC | P31: -5
A32: 44104 | B32: 水 | I32: KFC | J32: 10

Sheet 202008
C1: 楊 | F1: 張 | I1: 菜 | L1: 閻 | O1: 朱 | R1: 黄
A2: 日付 | B2: 曜日 | C2: =SUM(D3:D32) -> 0 | F2: =SUM(G:G) -> 0 | I2: =SUM(J:J) -> 10 | L2: =SUM(M:M) -> -20.5 | O2: =SUM(P:P) -> -25 | R2: =SUM(S:S) -> 10
A3: 44044 | B3: 土
A4: 44045 | B4: 日
A5: 44046 | B5: 月 | O5: KFC | P5: -5
A6: 44047 | B6: 火 | O6: KFC | P6: -5
A7: 44048 | B7: 水
A8: 44049 | B8: 木 | O8: KFC | P8: -5
A9: 44050 | B9: 金 | O9: KFC | P9: -5
A10: 44051 | B10: 土
A11: 44052 | B11: 日
A12: 44053 | B12: 月 | O12: KFC | P12: -5
A13: 44054 | B13: 火 | O13: KFC | P13: -5
A14: 44055 | B14: 水 | O14: スターバックス | P14: 19
A15: 44056 | B15: 木 | O15: KFC | P15: 15
A16: 44057 | B16: 金
A17: 44058 | B17: 土
A18: 44059 | B18: 日
A19: 44060 | B19: 月 | O19: KFC | P19: -5
A20: 44061 | B20: 火 | O20: KFC | P20: -5
A21: 44062 | B21: 水
A22: 44063 | B22: 木 | O22: KFC | P22: -15
A23: 44064 | B23: 金 | R23: KFC | S23: 5
A24: 44065 | B24: 土
A25: 44066 | B25: 日
A26: 44067 | B26: 月 | O26: KFC | P26: -5
A27: 44068 | B27: 火 | O27: KFC | P27: -5
A28: 44069 | B28: 水 | L28: スターバックス | M28: -20.5 | O28: スターバックス | P28: 21
A29: 44070 | B29: 木 | I29: KFC | J29: 10 | O29: KFC | P29: -5 | R29: KFC | S29: 5
A30: 44071 | B30: 金 | O30: KFC | P30: -5
A31: 44072 | B31: 土
A32: 44073 | B32: 日
A33: 44074 | B33: 月 | O33: KFC | P33: -5

Sheet 202007
C1: 楊 | F1: 張 | I1: 菜 | L1: 閻 | O1: 朱 | R1: 黄
A2: 日付 | B2: 曜日 | C2: =SUM(D3:D32) -> 0 | F2: =SUM(G:G) -> 0 | I2: =SUM(J:J) -> 0 | L2: =SUM(M:M) -> -127 | O2: =SUM(P:P) -> 41.5 | R2: =SUM(S:S) -> 16
A3: 44013 | B3: 水
A4: 44014 | B4: 木
A5: 44015 | B5: 金 | L5: スターバックス | M5: -44
A6: 44016 | B6: 土
A7: 44017 | B7: 日
A8: 44018 | B8: 月
A9: 44019 | B9: 火
A10: 44020 | B10: 水
A11: 44021 | B11: 木
A12: 44022 | B12: 金 | L12: スターバックス | M12: -44
A13: 44023 | B13: 土
A14: 44024 | B14: 日
A15: 44025 | B15: 月
A16: 44026 | B16: 火
A17: 44027 | B17: 水
A18: 44028 | B18: 木
A19: 44029 | B19: 金 | L19: スターバックス | M19: -39
A20: 44030 | B20: 土
A21: 44031 | B21: 日
A22: 44032 | B22: 月 | O22: KFC | P22: -5
A23: 44033 | B23: 火 | O23: KFC | P23: -5 | R23: KFC | S23: 6
A24: 44034 | B24: 水 | O24: スターバックス | P24: 22
A25: 44035 | B25: 木 | R25: KFC | S25: 10
A26: 44036 | B26: 金
A27: 44037 | B27: 土
A28: 44038 | B28: 日
A29: 44039 | B29: 月
A30: 44040 | B30: 火
A31: 44041 | B31: 水 | O31: KFC | P31: 19.5
A32: 44042 | B32: 木 | O32: KFC | P32: 10
A33: 44043 | B33: 金

Sheet 202006
C1: 楊 | F1: 張 | I1: 菜 | L1: 閻 | O1: 朱 | R1: 黄
A2: 日付 | B2: 曜日 | C2: =SUM(D3:D32) -> 0 | F2: =SUM(G:G) -> 0 | I2: =SUM(J:J) -> 0 | L2: =SUM(M:M) -> 40 | O2: =SUM(P:P) -> 0 | R2: =SUM(S:S) -> -178
A3: 43983 | B3: 月
A4: 43984 | B4: 火
A5: 43985 | B5: 水 | R5: スターバックス | S5: 22
A6: 43986 | B6: 木
A7: 43987 | B7: 金
A8: 43988 | B8: 土
A9: 43989 | B9: 日
A10: 43990 | B10: 月
A11: 43991 | B11: 火
A12: 43992 | B12: 水
A13: 43993 | B13: 木
A14: 43994 | B14: 金
A15: 43995 | B15: 土
A16: 43996 | B16: 日
A17: 43997 | B17: 月
... A25: 44005 | B25: 火
A26: 44006 | B26: 水 | L26: スターバックス | M26: 40
A27: 44007 | B27: 木
A28: 44008 | B28: 金
A29: 44009 | B29: 土
A30: 44010 | B30: 日
A31: 44011 | B31: 月
A32: 44012 | B32: 火 | R32: 精算 | S32: -200

Sheet 202005
C1: 楊 | F1: 張 | I1: 菜 | L1: 閻 | O1: 朱 | R1: 黄
A2: 日付 | B2: 曜日 | C2: =SUM(D3:D32) -> 0 | F2: =SUM(G:G) -> 0 | I2: =SUM(J:J) -> 0 | L2: =SUM(M:M) -> 0 | O2: =SUM(P:P) -> 0 | R2: =SUM(S:S) -> 123
A3: 43952 | B3: 金
A4: 43953 | B4: 土
A5: 43954 | B5: 日
A6: 43955 | B6: 月 | R6: 午後茶 | S6: 17
A7: 43956 | B7: 火
A8: 43957 | B8: 水 | R8: スターバックス | S8: 19
A9: 43958 | B9: 木
A10: 43959 | B10: 金
A11: 43960 | B11: 土
A12: 43961 | B12: 日
A13: 43962 | B13: 月 | R13: KFC | S13: 7
A14: 43963 | B14: 火 | R14: KFC | S14: 12
A15: 43964 | B15: 水 | R15: KFC | S15: 7
A16: 43965 | B16: 木
A17: 43966 | B17: 金 | R17: KFC | S17: 7
A18: 43967 | B18: 土
A19: 43968 | B19: 日
A20: 43969 | B20: 月
A21: 43970 | B21: 火
A22: 43971 | B22: 水
A23: 43972 | B23: 木
A24: 43973 | B24: 金 | R24: KFC | S24: 13
A25: 43974 | B25: 土
A26: 43975 | B26: 日
A27: 43976 | B27: 月 | R27: KFC | S27: 7
A28: 43977 | B28: 火
A29: 43978 | B29: 水 | R29: スターバックス | S29: 22
A30: 43979 | B30: 木 | R30: KFC | S30: 12
A31: 43980 | B31: 金
A32: 43981 | B32: 土
A33: 43982 | B33: 日

Sheet 202004
C1: 楊 | F1: 張 | I1: 菜 | L1: 閻 | O1: 朱 | R1: 黄
A2: 日付 | B2: 曜日 | C2: =SUM(D3:D33) -> 0 | F2: =SUM(G:G) -> 83 | I2: =SUM(J:J) -> -144.5 | L2: =SUM(M:M) -> 47 | O2: =SUM(P:P) -> 0 | R2: =SUM(S:S) -> -91.9
A3: 43922 | B3: 水
A4: 43923 | B4: 木
A5: 43924 | B5: 金 | F5: スタンド | G5: 83 | R5: ファン | S5: 57.7
A6: 43925 | B6: 土
A7: 43926 | B7: 日
A8: 43927 | B8: 月
A9: 43928 | B9: 火 | I9: KFC | J9: 18.5
A10: 43929 | B10: 水 | R10: KFC | S10: 13
A11: 43930 | B11: 木 | I11: 精算 | J11: -170 | L11: KFC | M11: 7 | R11: KFC | S11: 7.5
A12: 43931 | B12: 金
A13: 43932 | B13: 土
A14: 43933 | B14: 日
A15: 43934 | B15: 月
A16: 43935 | B16: 火 | R16: 精算 | S16: -60
R17: 精算 | S17: -160
A18: 43936 | B18: 水 | L18: 精算 | M18: 40
A19: 43937 | B19: 木 | I19: KFC | J19: 7 | R19: KFC | S19: 7
A20: 43938 | B20: 金
A21: 43939 | B21: 土
A22: 43940 | B22: 日
A23: 43941 | B23: 月 | R23: KFC | S23: 7
A24: 43942 | B24: 火 | R24: KFC | S24: 9.9
A25: 43943 | B25: 水
A26: 43944 | B26: 木 | R26: KFC | S26: 14
A27: 43945 | B27: 金 | R27: KFC | S27: 6
A28: 43946 | B28: 土
A29: 43947 | B29: 日
A30: 43948 | B30: 月
A31: 43949 | B31: 火
A32: 43950 | B32: 水
A33: 43951 | B33: 木 | R33: KFC | S33: 6

Sheet 202003
C1: 楊 | F1: 張 | I1: 菜 | L1: 閻 | O1: 朱 | R1: 黄
A2: 日付 | B2: 曜日 | C2: =SUM(D3:D35) -> 0 | F2: =SUM(G:G) -> 0 | I2: =SUM(J:J) -> 43 | L2: =SUM(M:M) -> 35 | O2: =SUM(P:P) -> -187 | R2: =SUM(S:S) -> 123
A3: 43891 | B3: 日
A4: 43892 | B4: 月 | R4: KFC | S4: 7
A5: 43893 | B5: 火 | R5: KFC | S5: 10
A6: 43894 | B6: 水
A7: 43895 | B7: 木 | I7: KFC | J7: 6 | O7: KFC | P7: -14
A8: 43896 | B8: 金 | O8: KFC | P8: -23 | R8: KFC | S8: 10
A9: 43897 | B9: 土
A10: 43898 | B10: 日
A11: 43899 | B11: 月 | R11: KFC | S11: 13
A12: 43900 | B12: 火 | L12: KFC | M12: 7 | R12: KFC | S12: 13
A13: 43901 | B13: 水 | L13: KFC | M13: 7
A14: 43902 | B14: 木 | L14: KFC | M14: 7 | O14: KFC | P14: 6.5
A15: 43903 | B15: 金 | I15: KFC | J15: 22 | L15: KFC | M15: 7
A16: 43904 | B16: 土
A17: 43905 | B17: 日
A18: 43906 | B18: 月 | L18: KFC | M18: 7 | R18: KFC | S18: 13
A19: 43907 | B19: 火 | R19: KFC | S19: 13
A20: 43908 | B20: 水 | I20: KFC | J20: 10
A21: 43909 | B21: 木 | O21: KFC | P21: =5+6.5 -> 11.5
A22: 43910 | B22: 金 | R22: KFC | S22: 13
A23: 43911 | B23: 土
A24: 43912 | B24: 日
A25: 43913 | B25: 月
A26: 43914 | B26: 火 | O26: らくらくティー | P26: 22
A27: 43915 | B27: 水 | R27: KFC | S27: 13
A28: 43916 | B28: 木 | I28: KFC | J28: 5 | O28: KFC | P28: -20 | R28: KFC | S28: 5
A29: 43917 | B29: 金 | O29: KFC | P29: -10 | R29: KFC | S29: 13
A30: 43918 | B30: 土
A31: 43919 | B31: 日
A32: 43920 | B32: 月
A33: 43921 | B33: 火 | O33: KFC | P33: -5
O34: 精算 | P34: -155

Sheet 202002
C1: 楊 | F1: 張 | I1: 菜 | L1: 閻 | O1: 朱 | R1: 黄
A2: 日付 | B2: 曜日 | C2: =SUM(D3:D34) -> 0 | F2: =SUM(G:G) -> -39 | I2: =SUM(J:J) -> 88 | L2: =SUM(M:M) -> 170 | O2: =SUM(P:P) -> 52 | R2: =SUM(S:S) -> -173
A3: 43862 | B3: 土
A4: 43863 | B4: 日
A5: 43864 | B5: 月
A6: 43865 | B6: 火
A7: 43866 | B7: 水
A8: 43867 | B8: 木
A9: 43868 | B9: 金
A10: 43869 | B10: 土
A11: 43870 | B11: 日
A12: 43871 | B12: 月 | F12: ティッシュペーパー | G12: 90
F13: 精算 | G13: 29
A14: 43872 | B14: 火 | I14: 朝食 | J14: 8 | O14: KFC | P14: 7
A15: 43873 | B15: 水 | I15: 朝食 | J15: 10 | L15: KFC | M15: 7 | O15: KFC | P15: 7
A16: 43874 | B16: 木 | I16: 朝食 | J16: 10
A17: 43875 | B17: 金
A18: 43876 | B18: 土
A19: 43877 | B19: 日
A20: 43878 | B20: 月 | I20: KFC | J20: 21 | O20: KFC | P20: 7
A21: 43879 | B21: 火 | R21: KFC | S21: 7
A22: 43880 | B22: 水 | L22: KFC | M22: 7 | R22: KFC | S22: 7
A23: 43881 | B23: 木 | I23: KFC | J23: 11 | R23: KFC | S23: 7
A24: 43882 | B24: 金 | F24: 精算 | G24: -158 | L24: 日本円精算 | M24: 156 | O24: KFC | P24: 6 | R24: KFC | S24: 7
A25: 43883 | B25: 土 | R25: KFC | S25: 14
A26: 43884 | B26: 日
A27: 43885 | B27: 月 | O27: KFC | P27: 7 | R27: KFC | S27: 7
R28: 入金 | S28: -250
A29: 43886 | B29: 火 | R29: KFC | S29: 7
A30: 43887 | B30: 水 | I30: KFC | J30: 28 | O30: KFC | P30: 6 | R30: KFC | S30: 7
A31: 43888 | B31: 木 | O31: KFC | P31: 7 | R31: KFC | S31: 7
O32: KFC | P32: 5
A33: 43889 | B33: 金 | R33: KFC | S33: 7
A34: 43890 | B34: 土

Sheet 202001
C1: 楊 | F1: 張 | I1: 菜 | L1: 閻 | O1: 朱 | R1: 黄
A2: 日付 | B2: 曜日 | C2: =SUM(D3:D37) -> 0 | F2: =SUM(G:G) -> -1174 | I2: =SUM(J:J) -> -461 | L2: =SUM(M:M) -> -227.5 | O2: =SUM(P:P) -> 178 | R2: =SUM(S:S) -> 248.5
A3: 43831 | B3: 水
A4: 43832 | B4: 木 | I4: 精算 | J4: -500 | O4: コーヒー | P4: -22.5 | R4: コーヒー | S4: 7.5
A5: 43833 | B5: 金 | F5: 昼ご飯 | G5: 39 | I5: 昼ご飯 | J5: 39 | O5: コーヒー | P5: -22.5 | R5: コーヒー | S5: 7.5
R6: 精算 | S6: 138
A7: 43834 | B7: 土
A8: 43835 | B8: 日
A9: 43836 | B9: 月 | O9: コーヒー | P9: -7.5 | R9: コーヒー | S9: 7.5
A10: 43837 | B10: 火 | R10: コーヒー | S10: 7.5
A11: 43838 | B11: 水 | R11: コーヒー | S11: 8.5
A12: 43839 | B12: 木 | F12: 昼ご飯 | G12: 22
A13: 43840 | B13: 金 | O13: KFC | P13: 8.5 | R13: コーヒー | S13: 7.5
A14: 43841 | B14: 土 | L14: コーヒー | M14: 7.5 | R14: コーヒー | S14: 7.5
A15: 43842 | B15: 日 | L15: コーヒー | M15: 7.5 | R15: コーヒー | S15: 7.5
R16: 精算 | S16: 127.5
A17: 43843 | B17: 月 | O17: タクシー代 | P17: =67+40 -> 107 | R17: コーヒー | S17: 8
R18: タクシー代 | S18: -67
A19: 43844 | B19: 火 | R19: コーヒー | S19: 8
A20: 43845 | B20: 水 | L20: コーヒー | M20: 7.5 | R20: コーヒー | S20: 8
A21: 43846 | B21: 木 | F21: 精算 | G21: -1274 | O21: タクシー代 | P21: 43 | R21: タクシー代 | S21: -65
F22: 昼ご飯 | G22: 39 | O22: タクシー代 | P22: 65 | R22: コーヒー | S22: 8
A23: 43847 | B23: 金 | R23: コーヒー | S23: 8
A24: 43848 | B24: 土
A25: 43849 | B25: 日
A26: 43850 | B26: 月 | O26: コーヒー | P26: 7 | R26: コーヒー | S26: 7
A27: 43851 | B27: 火 | L27: 精算 | M27: -250 | R27: コーヒー | S27: 7
A28: 43852 | B28: 水
A29: 43853 | B29: 木
A30: 43854 | B30: 金
A31: 43855 | B31: 土
A32: 43856 | B32: 日
A33: 43857 | B33: 月
A34: 43858 | B34: 火
A35: 43859 | B35: 水
A36: 43860 | B36: 木
A37: 43861 | B37: 金

Sheet 201912
C1: 楊 | F1: 張 | I1: 菜 | L1: 閻 | O1: 朱 | R1: 黄
A2: 日付 | B2: 曜日 | C2: =SUM(D3:D36) -> 0 | F2: =SUM(G:G) -> 303 | I2: =SUM(J:J) -> 31 | L2: =SUM(M:M) -> -146 | O2: =SUM(P:P) -> -71 | R2: =SUM(S:S) -> 131.7
A3: 43800 | B3: 日
A4: 43801 | B4: 月 | O4: コーヒー | P4: 7.5
A5: 43802 | B5: 火 | R5: KFC | S5: 6
R6: 午後茶 | S6: 28
A7: 43803 | B7: 水 | R7: コーヒー | S7: 6
A8: 43804 | B8: 木
A9: 43805 | B9: 金
A10: 43806 | B10: 土
A11: 43807 | B11: 日
A12: 43808 | B12: 月 | O12: コーヒー | P12: -7.5
A13: 43809 | B13: 火 | O13: コーヒー | P13: -8
A14: 43810 | B14: 水
A15: 43811 | B15: 木 | O15: KFC | P15: 7.5
O16: スターバックス | P16: -19
A17: 43812 | B17: 金
A18: 43813 | B18: 土 | O18: コーヒー | P18: -8
A19: 43814 | B19: 日
A20: 43815 | B20: 月 | O20: コーヒー | P20: 7.5 | R20: コーヒー | S20: 7.5
A21: 43816 | B21: 火 | L21: スプリング | M21: 34
A22: 43817 | B22: 水 | O22: マウスパッド | P22: 44 | R22: コーヒー | S22: 10
A23: 43818 | B23: 木
A24: 43819 | B24: 金 | F24: 昼ご飯 | G24: 29 | R24: コーヒー | S24: 7.5
A25: 43820 | B25: 土
A26: 43821 | B26: 日
A27: 43822 | B27: 月 | F27: 昼ご飯 | G27: 39 | O27: コーヒー | P27: 7.5
A28: 43823 | B28: 火 | F28: ティッシュペーパー | G28: 100 | O28: コーヒー | P28: -7.5 | R28: コーヒー | S28: 7.5
F29: 昼ご飯 | G29: 30
A30: 43824 | B30: 水 | O30: 精算 | P30: -65 | R30: 精算 | S30: =900-863.3 -> 36.7
A31: 43825 | B31: 木 | F31: 昼ご飯 | G31: 39 | O31: コーヒー | P31: 7.5 | R31: コーヒー | S31: 7.5
A32: 43826 | B32: 金 | F32: 昼ご飯 | G32: 35
A33: 43827 | B33: 土
A34: 43828 | B34: 日
A35: 43829 | B35: 月 | L35: 精算 | M35: -180 | O35: コーヒー | P35: -15 | R35: コーヒー | S35: 7.5
A36: 43830 | B36: 火 | F36: 昼ご飯 | G36: 31 | I36: 昼ご飯 | J36: 31 | O36: コーヒー | P36: -22.5 | R36: コーヒー | S36: 7.5

Sheet 201911
C1: 楊 | F1: 張 | I1: 菜 | L1: 閻 | O1: 朱 | R1: 黄
A2: 日付 | B2: 曜日 | C2: =SUM(D3:D36) -> 0 | F2: =SUM(G:G) -> 339.5 | I2: =SUM(J:J) -> 212 | L2: =SUM(M:M) -> 30 | O2: =SUM(P:P) -> -58 | R2: =SUM(S:S) -> -208
A3: 43770 | B3: 金
A4: 43771 | B4: 土 | F4: 精算 | G4: 350
A5: 43772 | B5: 日 | F5: 精算 | G5: 398 | O5: ICE | P5: 7
O6: 精算 | P6: -100
A7: 43773 | B7: 月 | I7: 昼ご飯 | J7: 26
A8: 43774 | B8: 火 | F8: 昼ご飯 | G8: 39 | I8: 昼ご飯 | J8: 39
A9: 43775 | B9: 水
A10: 43776 | B10: 木
A11: 43777 | B11: 金
A12: 43778 | B12: 土
A13: 43779 | B13: 日
A14: 43780 | B14: 月 | F14: 精算 | G14: 68 | O14: コーヒー | P14: 9 | R14: コーヒー | S14: 9
A15: 43781 | B15: 火 | F15: 精算 | G15: 103
A16: 43782 | B16: 水 | F16: 精算 | G16: 176 | I16: KFC | J16: 4 | R16: KFC | S16: 6
I17: 昼ご飯 | J17: 42
A18: 43783 | B18: 木 | I18: 昼ご飯 | J18: 32
A19: 43784 | B19: 金 | O19: スターバックス | P19: -21.5 | R19: スターバックス | S19: 20
A20: 43785 | B20: 土 | O20: ICE | P20: 5 | R20: 精算 | S20: -260
R21: コーヒー | S21: 6
A22: 43786 | B22: 日
A23: 43787 | B23: 月
A24: 43788 | B24: 火 | I24: 昼ご飯 | J24: 29
A25: 43789 | B25: 水
A26: 43790 | B26: 木 | O26: コーヒー | P26: 8.5 | R26: KFC | S26: 5
O27: KFC | P27: 5
A28: 43791 | B28: 金 | O28: コーヒー | P28: -8.5
A29: 43792 | B29: 土
A30: 43793 | B30: 日
A31: 43794 | B31: 月
A32: 43795 | B32: 火 | F32: 精算 | G32: -794.5 | I32: 昼ご飯 | J32: 40 | R32: コーヒー | S32: 6
A33: 43796 | B33: 水 | O33: スターバックス | P33: 17.5
A34: 43797 | B34: 木
A35: 43798 | B35: 金 | O35: スターバックス | P35: 20
A36: 43799 | B36: 土 | L36: 精算 | M36: 30

Sheet 201910
C1: 楊 | F1: 張 | I1: 菜 | L1: 閻 | O1: 朱 | R1: 黄
A2: 日付 | B2: 曜日 | C2: =SUM(D3:D32) -> 0 | F2: =SUM(G:G) -> 578 | I2: =SUM(J:J) -> 136 | L2: =SUM(M:M) -> 9 | O2: =SUM(P:P) -> 12.5 | R2: =SUM(S:S) -> 0
A3: 43739 | B3: 火
A4: 43740 | B4: 水
A5: 43741 | B5: 木
A6: 43742 | B6: 金
A7: 43743 | B7: 土
A8: 43744 | B8: 日
A9: 43745 | B9: 月
A10: 43746 | B10: 火
A11: 43747 | B11: 水 | O11: コーヒー | P11: 7.5
A12: 43748 | B12: 木 | F12: 精算 | G12: 102
A13: 43749 | B13: 金
A14: 43750 | B14: 土
A15: 43751 | B15: 日
A16: 43752 | B16: 月 | F16: 昼ご飯 | G16: 38 | I16: 昼ご飯 | J16: 38
A17: 43753 | B17: 火 | L17: 精算 | M17: 9
A18: 43754 | B18: 水 | F18: 昼ご飯 | G18: 32 | I18: 昼ご飯 | J18: 32 | O18: KFC | P18: 5
A19: 43755 | B19: 木
A20: 43756 | B20: 金
A21: 43757 | B21: 土
A22: 43758 | B22: 日
A23: 43759 | B23: 月
A24: 43760 | B24: 火 | F24: 精算 | G24: 174
A25: 43761 | B25: 水 | F25: 精算 | G25: 106
A26: 43762 | B26: 木 | F26: 精算 | G26: 148 | I26: 昼ご飯 | J26: 36
A27: 43763 | B27: 金
A28: 43764 | B28: 土
A29: 43765 | B29: 日
A30: 43766 | B30: 月 | F30: 精算 | G30: -52
A31: 43767 | B31: 火
A32: 43768 | B32: 水
A33: 43769 | B33: 木 | F33: 精算 | G33: 30 | I33: 精算 | J33: 30

Sheet 201909
C1: 楊 | F1: 張 | I1: 菜 | L1: 閻 | O1: 朱 | R1: 黄
A2: 日付 | B2: 曜日 | C2: =SUM(D3:D32) -> 0 | F2: =SUM(G:G) -> -44 | I2: =SUM(J:J) -> 56 | L2: =SUM(M:M) -> 0 | O2: =SUM(P:P) -> 73.6 | R2: =SUM(S:S) -> 20
A3: 43709 | B3: 日
A4: 43710 | B4: 月
A5: 43711 | B5: 火 | F5: 昼ご飯 | G5: 28 | I5: 昼ご飯 | J5: 28
A6: 43712 | B6: 水
A7: 43713 | B7: 木
A8: 43714 | B8: 金
A9: 43715 | B9: 土
A10: 43716 | B10: 日
A11: 43717 | B11: 月
A12: 43718 | B12: 火
A13: 43719 | B13: 水
A14: 43720 | B14: 木
A15: 43721 | B15: 金
A16: 43722 | B16: 土
A17: 43723 | B17: 日
A18: 43724 | B18: 月 | F18: 昼ご飯 | G18: 28 | I18: 昼ご飯 | J18: 28
A19: 43725 | B19: 火
A20: 43726 | B20: 水 | F20: 入金 | G20: -100
A21: 43727 | B21: 木
A22: 43728 | B22: 金
A23: 43729 | B23: 土
A24: 43730 | B24: 日
A25: 43731 | B25: 月
A26: 43732 | B26: 火
A27: 43733 | B27: 水 | O27: コーヒー | P27: 13.6
A28: 43734 | B28: 木 | O28: スターバックス | P28: 20 | R28: スターバックス | S28: 20
A29: 43735 | B29: 金 | O29: スターバックス | P29: 20
A30: 43736 | B30: 土
A31: 43737 | B31: 日
A32: 43738 | B32: 月 | O32: スターバックス | P32: 20

Sheet 201908
C1: 楊 | F1: 張 | I1: 菜 | L1: 閻 | O1: 朱 | R1: 黄
A2: 日付 | B2: 曜日 | C2: =SUM(D3:D35) -> 0 | F2: =SUM(G:G) -> -387.3 | I2: =SUM(J:J) -> -123 | L2: =SUM(M:M) -> -60 | O2: =SUM(P:P) -> -186.5 | R2: =SUM(S:S) -> 0
A3: 43678 | B3: 木
A4: 43679 | B4: 金
A5: 43680 | B5: 土
A6: 43681 | B6: 日
A7: 43682 | B7: 月 | F7: 精算 | G7: =-45-26.3 -> -71.3 | O7: ユニクロ | P7: =90*3 -> 270
A8: 43683 | B8: 火 | O8: コーヒー | P8: 6
A9: 43684 | B9: 水 | F9: コーヒー | G9: 6 | O9: コーヒー | P9: 6
A10: 43685 | B10: 木 | O10: コーヒー | P10: -6
A11: 43686 | B11: 金
A12: 43687 | B12: 土
A13: 43688 | B13: 日
A14: 43689 | B14: 月
A15: 43690 | B15: 火
A16: 43691 | B16: 水
A17: 43692 | B17: 木 | O17: コーヒー | P17: -6
A18: 43693 | B18: 金
A19: 43694 | B19: 土
A20: 43695 | B20: 日
A21: 43696 | B21: 月
A22: 43697 | B22: 火
A23: 43698 | B23: 水
A24: 43699 | B24: 木 | F24: 昼ご飯 | G24: 40 | I24: 昼ご飯 | J24: 40 | O24: コーヒー | P24: 8
I25: 入金 | J25: -200
A26: 43700 | B26: 金 | O26: コーヒー | P26: -6
A27: 43701 | B27: 土
A28: 43702 | B28: 日
A29: 43703 | B29: 月 | F29: 昼ご飯 | G29: 20
F30: 精算 | G30: -190
A31: 43704 | B31: 火 | F31: 精算 | G31: -29 | O31: 入金 | P31: -458.5
A32: 43705 | B32: 水 | F32: 入金 | G32: -200 | L32: スターバックス | M32: -20
A33: 43706 | B33: 木 | L33: スターバックス | M33: -20
A34: 43707 | B34: 金 | F34: 昼ご飯 | G34: 37 | I34: 昼ご飯 | J34: 37 | L34: スターバックス | M34: -20
A35: 43708 | B35: 土

Sheet 201906
C1: 楊 | F1: 張 | I1: 菜 | L1: 閻 | O1: 朱 | R1: 黄
A2: 日付 | B2: 曜日 | C2: =SUM(D3:D41) -> 0 | F2: =SUM(G:G) -> 440.5 | I2: =SUM(J:J) -> 157 | L2: =SUM(M:M) -> 17 | O2: =SUM(P:P) -> 139.5 | R2: =SUM(S:S) -> -20
A3: 43617 | B3: 土 | F3: コーヒー | G3: 6
A4: 43618 | B4: 日
A5: 43619 | B5: 月 | F5: コーヒー | G5: 6
A6: 43620 | B6: 火 | F6: コーヒー | G6: 6 | O6: KFC | P6: 12.5
A7: 43621 | B7: 水 | F7: コーヒー | G7: 6 | I7: 昼ごはん | J7: 38 | R7: 午後茶 | S7: 22
F8: 昼ごはん | G8: 38
A9: 43622 | B9: 木 | F9: コーヒー | G9: 6 | O9: KFC | P9: 9 | R9: KFC | S9: 9
R10: 精算 | S10: -44
A11: 43623 | B11: 金 | F11: コーヒー | G11: 6
A12: 43624 | B12: 土
A13: 43625 | B13: 日
A14: 43626 | B14: 月 | F14: コーヒー | G14: 6
A15: 43627 | B15: 火 | F15: コーヒー | G15: 6 | L15: KFC | M15: =9+8 -> 17 | R15: KFC | S15: 9
A16: 43628 | B16: 水 | F16: コーヒー | G16: 6 | I16: 昼ごはん | J16: 28 | O16: コーヒー | P16: 6
F17: 昼ごはん | G17: 28 | O17: KFC | P17: 9
A18: 43629 | B18: 木 | O18: KFC | P18: 9 | R18: KFC | S18: 9
A19: 43630 | B19: 金 | F19: 昼ごはん | G19: 20 | I19: 昼ごはん | J19: 27 | R19: 午後茶 | S19: 20
A20: 43631 | B20: 土
A21: 43632 | B21: 日
A22: 43633 | B22: 月 | F22: コーヒー | G22: 6 | O22: 午後茶 | P22: 16 | R22: 午後茶 | S22: 16
A23: 43634 | B23: 火 | F23: コーヒー | G23: 6
A24: 43635 | B24: 水 | F24: コーヒー | G24: 6 | O24: 午後茶 | P24: 8 | R24: 午後茶 | S24: 20
F25: 入金 | G25: -44
A26: 43636 | B26: 木 | F26: 昼ご飯 | G26: 22 | I26: 昼ご飯 | J26: 20
F27: 午後茶 | G27: 18
A28: 43637 | B28: 金 | F28: 昼ご飯 | G28: 36 | O28: 午後茶 | P28: 14
F29: 昼ご飯（xin） | G29: 36
F30: 午後茶 | G30: 19
A31: 43638 | B31: 土
A32: 43639 | B32: 日
A33: 43640 | B33: 月
A34: 43641 | B34: 火 | F34: 午後茶 | G34: 19 | O34: 午後茶 | P34: 20 | R34: 午後茶 | S34: 16
A35: 43642 | B35: 水 | F35: 昼ご飯 | G35: 39 | I35: 昼ご飯 | J35: 44 | R35: 午後茶 | S35: 18
A36: 43643 | B36: 木 | F36: 午後茶 | G36: 19 | O36: 午後茶 | P36: 18
F37: 精算 | G37: 192
A38: 43644 | B38: 金 | F38: 入金 | G38: -497 | O38: 午後茶 | P38: 18 | R38: 入金 | S38: -115
F39: 精算 | G39: 423.5
A40: 43645 | B40: 土
...

Sheet 201905
C1: 楊 | F1: 張 | I1: 菜 | L1: 閻 | O1: 朱 | R1: 黄
A2: 日付 | B2: 曜日 | C2: =SUM(D3:D47) -> 0 | F2: =SUM(G:G) -> -22.6 | I2: =SUM(J:J) -> 121.8 | L2: =SUM(M:M) -> -8 | O2: =SUM(P:P) -> 47 | R2: =SUM(S:S) -> 20
A3: 43586 | B3: 水
A4: 43587 | B4: 木 | F4: 昼ご飯 | G4: 40 | I4: 昼ご飯 | J4: 40 | L4: 精算 | M4: -8
F5: コーヒー | G5: 6
A6: 43588 | B6: 金 | F6: コーヒー | G6: 6 | I6: 飲み物 | J6: 13.5
A7: 43589 | B7: 土 | F7: コーヒー | G7: 8 | I7: アイス | J7: 12.8
A8: 43590 | B8: 日 | F8: 精算 | G8: 96
A9: 43591 | B9: 月 | F9: コーヒー | G9: 6
A10: 43592 | B10: 火 | F10: コーヒー | G10: 6
A11: 43593 | B11: 水 | F11: コーヒー | G11: 6
A12: 43594 | B12: 木 | F12: コーヒー | G12: 6 | I12: 昼ご飯 | J12: 42
F13: 食事精算 | G13: -232
F14: 昼ご飯 | G14: 42
A15: 43595 | B15: 金 | F15: タクシー代精算 | G15: 41
F16: コーヒー | G16: 6
A17: 43596 | B17: 土
A18: 43597 | B18: 日
A19: 43598 | B19: 月 | F19: コーヒー | G19: 7.5 | I19: 昼ご飯 | J19: 31
F20: 昼ご飯 | G20: 31
A21: 43599 | B21: 火 | F21: コーヒー | G21: 6 | I21: 昼ご飯 | J21: 38 | O21: KFC | P21: 9
F22: 昼ご飯 | G22: 33 | I22: 入金 | J22: -200
A23: 43600 | B23: 水 | F23: コーヒー | G23: 6
F24: 昼ご飯 | G24: 20
A25: 43601 | B25: 木 | F25: コーヒー | G25: 6
F26: 昼ご飯 | G26: -23
F27: 入金 | G27: -131
A28: 43602 | B28: 金
A29: 43603 | B29: 土
A30: 43604 | B30: 日
A31: 43605 | B31: 月 | F31: コーヒー | G31: 7.5 | I31: 昼ご飯 | J31: 25 | O31: コーヒー | P31: -6
F32: 昼ご飯 | G32: 20 | O32: コーヒー | P32: -6
A33: 43606 | B33: 火 | F33: 昼ご飯 | G33: 10.5 | I33: 昼ご飯 | J33: -18 | O33: KFC | P33: 9
F34: コーヒー | G34: 6 | I34: 昼ご飯 | J34: -10.5
A35: 43607 | B35: 水 | F35: コーヒー | G35: 6 | O35: コーヒー | P35: -6
O36: アイス | P36: 6
A37: 43608 | B37: 木 | F37: コーヒー | G37: 6 | I37: 昼ご飯 | J37: 47 | O37: コーヒー | P37: -12
F38: 昼ご飯 | G38: 42 | O38: 午後茶 | P38: 13
F39: 入金 | G39: -114
A40: 43609 | B40: 金 | F40: コーヒー | G40: 17.5 | O40: KFC | P40: 9
...

Sheet 201904
C1: 楊 | F1: 張 | I1: 菜 | L1: 閻
A2: 日付 | B2: 曜日 | C2: =SUM(D3:D39) -> 0 | F2: =SUM(G3:G39) -> -232.9 | I2: =SUM(J3:J39) -> -256 | L2: =SUM(M3:M39) -> -142
A3: 43556 | B3: 月 | F3: コーヒー | G3: 6 | I3: 昼ご飯 | J3: 42
F4: 昼ご飯 | G4: 80
A5: 43557 | B5: 火 | F5: コーヒー | G5: 6
F6: 昼ご飯 | G6: -29
A7: 43558 | B7: 水 | F7: コーヒー | G7: 6
F8: 食事精算 | G8: 66
A9: 43559 | B9: 木
A10: 43560 | B10: 金
A11: 43561 | B11: 土
A12: 43562 | B12: 日 | F12: 食事精算 | G12: 87
A13: 43563 | B13: 月
A14: 43564 | B14: 火
A15: 43565 | B15: 水 | F15: コーヒー | G15: 6 | I15: 昼ご飯 | J15: 27
A16: 43566 | B16: 木 | F16: コーヒー | G16: 6 | I16: 昼ご飯 | J16: 40
F17: 昼ご飯 | G17: 40
F18: 食事精算 | G18: 125.3
A19: 43567 | B19: 金
A20: 43568 | B20: 土
A21: 43569 | B21: 日
A22: 43570 | B22: 月
A23: 43571 | B23: 火
A24: 43572 | B24: 水
A25: 43573 | B25: 木
A26: 43574 | B26: 金
A27: 43575 | B27: 土 | I27: 入金 | J27: -200
I28: コーヒー | J28: 16
A29: 43576 | B29: 日
A30: 43577 | B30: 月 | F30: 精算 | G30: -638.2
A31: 43578 | B31: 火
A32: 43579 | B32: 水
A33: 43580 | B33: 木
A34: 43581 | B34: 金 | L34: 懸念事項 | M34: -150
L35: コーヒー | M35: 8
A36: 43582 | B36: 土
A37: 43583 | B37: 日
A38: 43584 | B38: 月
A39: 43585 | B39: 火 | F39: コーヒー | G39: 6 | I39: 入金 | J39: -181

Sheet 201903
C1: 楊 | F1: 張 | I1: 菜 | L1: 閻
A2: 日付 | B2: 曜日 | C2: =SUM(D3:D33) -> 0 | F2: =SUM(G3:G33) -> 208 | I2: =SUM(J3:J33) -> 151 | L2: =SUM(M3:M33) -> 0
A3: 43525 | B3: 金
A4: 43526 | B4: 土
A5: 43527 | B5: 日
A6: 43528 | B6: 月
A7: 43529 | B7: 火
A8: 43530 | B8: 水
A9: 43531 | B9: 木
A10: 43532 | B10: 金
A11: 43533 | B11: 土
A12: 43534 | B12: 日
A13: 43535 | B13: 月 | I13: 昼ご飯 | J13: 42
A14: 43536 | B14: 火
A15: 43537 | B15: 水
A16: 43538 | B16: 木
A17: 43539 | B17: 金 | I17: 服 | J17: 69
A18: 43540 | B18: 土
A19: 43541 | B19: 日
A20: 43542 | B20: 月 | I20: 昼ご飯 | J20: 40
A21: 43543 | B21: 火
A22: 43544 | B22: 水 | F22: 入金 | G22: -31
A23: 43545 | B23: 木
A24: 43546 | B24: 金
A25: 43547 | B25: 土
A26: 43548 | B26: 日
A27: 43549 | B27: 月
A28: 43550 | B28: 火 | F28: 食事精算 | G28: =111+57 -> 168
A29: 43551 | B29: 水 | F29: コーヒー | G29: 8
A30: 43552 | B30: 木 | F30: 食事精算 | G30: 63
A31: 43553 | B31: 金
A32: 43554 | B32: 土
A33: 43555 | B33: 日

Sheet 201902
C1: 楊 | F1: 張 | I1: 菜 | L1: 閻
A2: 日付 | B2: 曜日 | C2: =SUM(D3:D33) -> 0 | F2: =SUM(G3:G33) -> 31.2 | I2: =SUM(J3:J33) -> -100 | L2: =SUM(M3:M33) -> 0
A3: 43497 | B3: 金
A4: 43498 | B4: 土 | F4: 昼ご飯 | G4: 38
A5: 43499 | B5: 日
A6: 43500 | B6: 月
A7: 43501 | B7: 火
A8: 43502 | B8: 水
A9: 43503 | B9: 木
A10: 43504 | B10: 金
A11: 43505 | B11: 土 | F11: 精算 | G11: =-(34.6+32.6+29.6) -> -96.8
F12: コーヒー | G12: 10
A13: 43506 | B13: 日
A14: 43507 | B14: 月
A15: 43508 | B15: 火
A16: 43509 | B16: 水 | F16: コーヒー | G16: 10
A17: 43510 | B17: 木 | F17: コーヒー | G17: 10 | I17: 昼ご飯 | J17: 40
B18: 金 | F18: 昼ご飯 | G18: 40
A19: 43511 | B19: 金 | F19: コーヒー | G19: 10
A20: 43512 | B20: 土
A21: 43513 | B21: 日
A22: 43514 | B22: 月 | I22: 昼ご飯 | J22: 25
B23: 火 | I23: 入金 | J23: -200
A24: 43515 | B24: 火 | F24: コーヒー | G24: 10
A25: 43516 | B25: 水
A26: 43517 | B26: 木 | I26: 昼ご飯 | J26: 35
A27: 43518 | B27: 金
A28: 43519 | B28: 土
A29: 43520 | B29: 日
A30: 43521 | B30: 月
A31: 43522 | B31: 火
A32: 43523 | B32: 水
A33: 43524 | B33: 木

Sheet 201901
C1: 楊 | F1: 張 | I1: 菜 | L1: 閻
A2: 日付 | B2: 曜日 | C2: =SUM(D3:D34) -> 0 | F2: =SUM(G3:G34) -> -531 | I2: =SUM(J3:J34) -> 83.5 | L2: =SUM(M3:M34) -> 0
A3: 43466 | B3: 火
A4: 43467 | B4: 水
A5: 43468 | B5: 木 | F5: 昼ご飯 | G5: 34 | I5: 昼ご飯 | J5: 24
A6: 43469 | B6: 金 | F6: コーヒー奢る | G6: 20
A7: 43470 | B7: 土 | F7: コーヒー | G7: 10
F8: KFC | G8: 85
A9: 43471 | B9: 日
A10: 43472 | B10: 月
A11: 43473 | B11: 火
A12: 43474 | B12: 水
A13: 43475 | B13: 木 | I13: 昼ご飯 | J13: -18
A14: 43476 | B14: 金
A15: 43477 | B15: 土
A16: 43478 | B16: 日
A17: 43479 | B17: 月 | I17: 昼ご飯 | J17: 38
A18: 43480 | B18: 火
A19: 43481 | B19: 水
A20: 43482 | B20: 木
A21: 43483 | B21: 金
A22: 43484 | B22: 土
A23: 43485 | B23: 日
A24: 43486 | B24: 月 | F24: 精算 | G24: -680
A25: 43487 | B25: 火
A26: 43488 | B26: 水 | I26: 昼ご飯 | J26: 30
A27: 43489 | B27: 木
A28: 43490 | B28: 金
A29: 43491 | B29: 土
A30: 43492 | B30: 日
A31: 43493 | B31: 月 | I31: 昼ご飯 | J31: -24.5
A32: 43494 | B32: 火
A33: 43495 | B33: 水 | I33: 昼ご飯 | J33: 34
A34: 43496 | B34: 木

Sheet 201812
C1: 楊 | F1: 張 | I1: 菜 | L1: 閻
A2: 日付 | B2: 曜日 | C2: =SUM(D3:D42) -> 0 | F2: =SUM(G3:G42) -> 530.5 | I2: =SUM(J3:J42) -> 0 | L2: =SUM(M3:M42) -> 0
A3: 43435 | B3: 土
A4: 43436 | B4: 日
A5: 43437 | B5: 月
A6: 43438 | B6: 火 | F6: コーヒー | G6: 8.5
A7: 43439 | B7: 水 | F7: コーヒー | G7: 7.5
A8: 43440 | B8: 木 | F8: コーヒー | G8: 8.5
F9: 昼ご飯 | G9: 19
F10: タクシー代 | G10: -22
A11: 43441 | B11: 金
A12: 43442 | B12: 土
A13: 43443 | B13: 日
A14: 43444 | B14: 月 | F14: コーヒー | G14: 7.5
F15: 精算 | G15: 70
F16: 昼ご飯 | G16: 40
A17: 43445 | B17: 火 | F17: コーヒー | G17: 7.5
A18: 43446 | B18: 水 | F18: コーヒー | G18: 7.5
F19: 昼ご飯 | G19: -21
A20: 43447 | B20: 木 | F20: コーヒー | G20: 7.5
A21: 43448 | B21: 金 | F21: コーヒー | G21: 7.5
A22: 43449 | B22: 土 | F22: コーヒー | G22: 10
A23: 43450 | B23: 日
A24: 43451 | B24: 月 | F24: コーヒー | G24: 7.5
F25: 午後茶 | G25: 7
A26: 43452 | B26: 火 | F26: コーヒー | G26: 7.5
A27: 43453 | B27: 水 | F27: コーヒー | G27: 7.5
A28: 43454 | B28: 木 | F28: スターバックス | G28: 20
A29: 43455 | B29: 金
A30: 43456 | B30: 土
A31: 43457 | B31: 日
A32: 43458 | B32: 月
A33: 43459 | B33: 火 | F33: コーヒー | G33: 8
F34: 昼ご飯 | G34: 36
A35: 43460 | B35: 水
A36: 43461 | B36: 木 | F36: タクシー代 | G36: 77
F37: 昼ご飯 | G37: -32
A38: 43462 | B38: 金 | F38: コーヒー | G38: 8
F39: 昼ご飯 | G39: -25
A40: 43463 | B40: 土 | F40: スターバックス | G40: 20
...

Sheet 201811
C1: 楊 | F1: 張 | I1: 菜 | L1: 閻
A2: 日付 | B2: 曜日 | C2: =SUM(D3:D35) -> 0 | F2: =SUM(G3:G35) -> 0 | I2: =SUM(J3:J35) -> 53.5 | L2: =SUM(M3:M35) -> -499
A3: 43405 | B3: 木
A4: 43406 | B4: 金
A5: 43407 | B5: 土
A6: 43408 | B6: 日
A7: 43409 | B7: 月
A8: 43410 | B8: 火
A9: 43411 | B9: 水 | I9: 昼ご飯 | J9: 40
A10: 43412 | B10: 木
A11: 43413 | B11: 金
A12: 43414 | B12: 土
A13: 43415 | B13: 日
A14: 43416 | B14: 月
A15: 43417 | B15: 火
A16: 43418 | B16: 水
A17: 43419 | B17: 木 | I17: 昼ご飯 | J17: 39 | L17: チャージ | M17: -700
L18: 精算 | M18: 51
A19: 43420 | B19: 金
A20: 43421 | B20: 土
A21: 43422 | B21: 日
A22: 43423 | B22: 月
A23: 43424 | B23: 火 | I23: 鶏 | J23: 45
I24: 午後茶 | J24: 6
A25: 43425 | B25: 水 | I25: KFC | J25: 29
A26: 43426 | B26: 木 | L26: スターバックス | M26: 150
A27: 43427 | B27: 金
A28: 43428 | B28: 土 | I28: コーヒー | J28: 8.5
A29: 43429 | B29: 日
A30: 43430 | B30: 月
A31: 43431 | B31: 火 | I31: サーリヤ | J31: 57
I32: 入金 | J32: -200
A33: 43432 | B33: 水
A34: 43433 | B34: 木
A35: 43434 | B35: 金 | I35: ジンギスカン | J35: 29

Sheet 201810
C1: 楊 | F1: 張 | I1: 菜 | L1: 閻
A2: 日付 | B2: 曜日 | C2: =SUM(D3:D37) -> 0 | F2: =SUM(G3:G39) -> -390.2 | I2: =SUM(J3:J39) -> -24.6 | L2: =SUM(M3:M39) -> 0
A3: 43374 | B3: 月
A4: 43375 | B4: 火
A5: 43376 | B5: 水 | F5: 食事精算 | G5: 38
A6: 43377 | B6: 木 | I6: 昼ご飯 | J6: 38
F7: 昼ご飯 | G7: 33
A8: 43378 | B8: 金 | F8: 朝ご飯 | G8: 8.8
F9: タクシー代 | G9: 32
A10: 43379 | B10: 土
A11: 43380 | B11: 日
A12: 43381 | B12: 月 | F12: 昼ご飯 | G12: -27
A13: 43382 | B13: 火
A14: 43383 | B14: 水 | F14: 昼ご飯 | G14: 35 | I14: 昼ご飯 | J14: 35
F15: タクシー代 | G15: 28 | I15: 精算 | J15: -100
A16: 43384 | B16: 木 | F16: タクシー代 | G16: 28
A17: 43385 | B17: 金
A18: 43386 | B18: 土
A19: 43387 | B19: 日
A20: 43388 | B20: 月
A21: 43389 | B21: 火 | F21: 精算 | G21: 34
F22: 精算 | G22: 37
F23: 精算 | G23: -637
A24: 43390 | B24: 水
A25: 43391 | B25: 木
A26: 43392 | B26: 金
A27: 43393 | B27: 土
A28: 43394 | B28: 日
A29: 43395 | B29: 月 | I29: 昼ご飯 | J29: -28.6
A30: 43396 | B30: 火
A31: 43397 | B31: 水
A32: 43398 | B32: 木
A33: 43399 | B33: 金
A34: 43400 | B34: 土
A35: 43401 | B35: 日
A36: 43402 | B36: 月 | I36: 奢り | J36: 158
A37: 43403 | B37: 火 | I37: 鶏 | J37: 40
A38: 43404 | B38: 水 | I38: 精算 | J38: -200
I39: 雲南 | J39: 33

Sheet 201809
C1: 楊 | F1: 張 | I1: 菜 | L1: 閻
A2: 日付 | B2: 曜日 | C2: =SUM(D3:D37) -> 0 | F2: =SUM(G3:G38) -> -81.5 | I2: =SUM(J3:J38) -> 37 | L2: =SUM(M3:M38) -> -250
A3: 43344 | B3: 土
A4: 43345 | B4: 日
A5: 43346 | B5: 月 | F5: タクシー代 | G5: 30
F6: コーヒー | G6: 7.5
A7: 43347 | B7: 火
A8: 43348 | B8: 水
A9: 43349 | B9: 木
A10: 43350 | B10: 金 | F10: 食事精算 | G10: -273
F11: コーヒー | G11: 7.5
A12: 43351 | B12: 土 | F12: 食事精算 | G12: -241
A13: 43352 | B13: 日
A14: 43353 | B14: 月 | F14: 昼ご飯 | G14: 37 | I14: 昼ご飯 | J14: 37
F15: コーヒー | G15: 7.5
A16: 43354 | B16: 火
A17: 43355 | B17: 水
A18: 43356 | B18: 木 | F18: 昼ご飯 | G18: -28
F19: タクシー代 | G19: 31
A20: 43357 | B20: 金 | F20: 昼ご飯 | G20: -6 | L20: 髪 | M20: -250
A21: 43358 | B21: 土
A22: 43359 | B22: 日
A23: 43360 | B23: 月
A24: 43361 | B24: 火
A25: 43362 | B25: 水
A26: 43363 | B26: 木
A27: 43364 | B27: 金
A28: 43365 | B28: 土
A29: 43366 | B29: 日
A30: 43367 | B30: 月
A31: 43368 | B31: 火
A32: 43369 | B32: 水
A33: 43370 | B33: 木 | F33: 午後茶 | G33: 9
F34: 食事精算 | G34: =228+49 -> 277
F35: 食事精算 | G35: 60
A36: 43371 | B36: 金
A37: 43372 | B37: 土
A38: 43373 | B38: 日

Sheet 201808
C1: 楊 | F1: 張 | I1: 菜 | L1: 閻
A2: 日付 | B2: 曜日 | C2: =SUM(D3:D34) -> 0 | F2: =SUM(G3:G37) -> 472.5 | I2: =SUM(J3:J37) -> -172 | L2: =SUM(M3:M37) -> -944.5
A3: 43313 | B3: 水
A4: 43314 | B4: 木
A5: 43315 | B5: 金
A6: 43316 | B6: 土
A7: 43317 | B7: 日
A8: 43318 | B8: 月 | I8: 午後茶 | J8: 15
A9: 43319 | B9: 火
A10: 43320 | B10: 水 | F10: 精算 | G10: -7
A11: 43321 | B11: 木 | F11: タクシー代 | G11: 29
A12: 43322 | B12: 金
A13: 43323 | B13: 土
A14: 43324 | B14: 日
A15: 43325 | B15: 月 | F15: 精算 | G15: -150 | I15: 昼ご飯 | J15: 38 | L15: 精算 | M15: -23.5
I16: 精算 | J16: -200
A17: 43326 | B17: 火 | F17: 精算 | G17: 600 | I17: 午後茶 | J17: 15
F18: 午後茶 | G18: 15
A19: 43327 | B19: 水 | I19: 昼ご飯 | J19: 50
A20: 43328 | B20: 木
A21: 43329 | B21: 金
A22: 43330 | B22: 土
A23: 43331 | B23: 日
A24: 43332 | B24: 月
A25: 43333 | B25: 火
A26: 43334 | B26: 水 | I26: 昼ご飯 | J26: 40
I27: 精算 | J27: -60
A28: 43335 | B28: 木 | F28: 精算 | G28: -486.5 | I28: 精算 | J28: -100 | L28: 精算 | M28: -878
A29: 43336 | B29: 金 | I29: 松屋 | J29: 30
A30: 43337 | B30: 土
A31: 43338 | B31: 日
A32: 43339 | B32: 月
A33: 43340 | B33: 火
A34: 43341 | B34: 水 | F34: スターバックス | G34: 20
F35: 残業食事 | G35: 208
A36: 43342 | B36: 木 | F36: 残業食事 | G36: 244
A37: 43343 | B37: 金 | L37: スターバックス | M37: -43

Sheet 201807
C1: 楊 | F1: 張 | I1: 菜 | L1: 閻
A2: 日付 | B2: 曜日 | C2: =SUM(D3:D35) -> 0 | F2: =SUM(G3:G37) -> -20.6 | I2: =SUM(J3:J37) -> 49 | L2: =SUM(M3:M37) -> 210
A3: 43282 | B3: 日
A4: 43283 | B4: 月
A5: 43284 | B5: 火 | I5: コーヒー | J5: 13
A6: 43285 | B6: 水 | F6: ファミリー | G6: 9
A7: 43286 | B7: 木
A8: 43287 | B8: 金 | F8: タクシー代 | G8: 30 | I8: 昼ご飯 | J8: 36
G9: -4
F10: 残業食事精算 | G10: -25
F11: 昼ご飯 | G11: 29
F12: 精算 | G12: -3.6
A13: 43288 | B13: 土 | F13: 残業食事精算 | G13: -33
A14: 43289 | B14: 日
A15: 43290 | B15: 月
A16: 43291 | B16: 火
A17: 43292 | B17: 水
A18: 43293 | B18: 木
A19: 43294 | B19: 金
A20: 43295 | B20: 土
A21: 43296 | B21: 日
A22: 43297 | B22: 月
A23: 43298 | B23: 火
A24: 43299 | B24: 水
A25: 43300 | B25: 木
... A32: 43307 | B32: 木
A33: 43308 | B33: 金 | L33: コーヒー | M33: 210
A34: 43309 | B34: 土
A35: 43310 | B35: 日
A36: 43311 | B36: 月
A37: 43312 | B37: 火 | F37: 残業食事精算 | G37: -23

Sheet 201806
C1: 楊 | F1: 張 | I1: 菜 | L1: 閻
A2: 日付 | B2: 曜日 | C2: =SUM(D3:D33) -> 0 | F2: =SUM(G3:G34) -> -86.5 | I2: =SUM(J3:J34) -> 30 | L2: =SUM(M3:M34) -> -25
A3: 43252 | B3: 火
A4: 43253 | B4: 水
A5: 43254 | B5: 木
A6: 43255 | B6: 金
A7: 43256 | B7: 土
A8: 43257 | B8: 日
A9: 43258 | B9: 月 | F9: 受入 | G9: -100 | I9: 昼ご飯 | J9: 30
A10: 43259 | B10: 火
A11: 43260 | B11: 水 | F11: 精算 | G11: -27
A12: 43261 | B12: 木
A13: 43262 | B13: 金 | F13: 昼ご飯 | G13: -20
F14: 釣り | G14: 55.5
A15: 43263 | B15: 土 | F15: タクシー代 | G15: =-18-18-19 -> -55
A16: 43264 | B16: 日 | F16: 晩ご飯 | G16: 151
A17: 43265 | B17: 月
A18: 43266 | B18: 火
A19: 43267 | B19: 水
A20: 43268 | B20: 木
A21: 43269 | B21: 金
A22: 43270 | B22: 土 | F22: 昼ご飯 | G22: -31
A23: 43271 | B23: 日 | F23: タクシー代 | G23: -18
A24: 43272 | B24: 月
A25: 43273 | B25: 火
A26: 43274 | B26: 水 | F26: タクシー代 | G26: -82 | L26: 髪 | M26: -25
A27: 43275 | B27: 木 | F27: 残業食事 | G27: 140
F28: タクシー代 | G28: -23
A29: 43276 | B29: 金
A30: 43277 | B30: 土
A31: 43278 | B31: 日
A32: 43279 | B32: 月
A33: 43280 | B33: 火 | F33: 受入 | G33: -100
A34: 43281 | B34: 水 | F34: 昼ご飯 | G34: 23

Sheet 201805
C1: 楊 | F1: 張 | I1: 菜 | L1: 閻
A2: 日付 | B2: 曜日 | C2: =SUM(D3:D37) -> 0 | F2: =SUM(G3:G39) -> 63.4 | I2: =SUM(J3:J39) -> 40 | L2: =SUM(M3:M39) -> 0
A3: 43221 | B3: 火
A4: 43222 | B4: 水 | F4: 釣り | G4: 135
F5: コーヒー | G5: 11
A6: 43223 | B6: 木 | F6: コーヒー | G6: 11 | I6: 午後茶 | J6: 15
A7: 43224 | B7: 金 | F7: コーヒー | G7: 11
A8: 43225 | B8: 土 | F8: 残業食事 | G8: 87
A9: 43226 | B9: 日
A10: 43227 | B10: 月 | F10: コーヒー | G10: 10.5 | I10: 昼ご飯 | J10: 35
F11: 受入 | G11: -100
A12: 43228 | B12: 火 | F12: 外食 | G12: -19
F13: 釣り | G13: 96
A14: 43229 | B14: 水
A15: 43230 | B15: 木
A16: 43231 | B16: 金
A17: 43232 | B17: 土
A18: 43233 | B18: 日
A19: 43234 | B19: 月
A20: 43235 | B20: 火 | F20: 外食 | G20: 20 | I20: コーヒー | J20: 13
A21: 43236 | B21: 水 | I21: 外食 | J21: 38
I22: 受入 | J22: -100
A23: 43237 | B23: 木
A24: 43238 | B24: 金
A25: 43239 | B25: 土
A26: 43240 | B26: 日
A27: 43241 | B27: 月 | F27: 残業食事 | G27: 19.9
A28: 43242 | B28: 火 | I28: 昼ご飯 | J28: 39
A29: 43243 | B29: 水 | F29: コーヒー | G29: 11
F30: 残業食事 | G30: 20
F31: 残業食事 | G31: 111
A32: 43244 | B32: 木 | F32: タクシー代精算 | G32: 28
A33: 43245 | B33: 金
A34: 43246 | B34: 土
A35: 43247 | B35: 日
A36: 43248 | B36: 月
A37: 43249 | B37: 火
A38: 43250 | B38: 水 | F38: コーヒー | G38: 11
A39: 43251 | B39: 木 | F39: 受入 | G39: -400

Sheet 201804
C1: 楊 | F1: 張 | I1: 菜 | L1: 閻
A2: 日付 | B2: 曜日 | C2: =SUM(D3:D35) -> 0 | F2: =SUM(G3:G36) -> -9 | I2: =SUM(J3:J36) -> -76 | L2: =SUM(M3:M36) -> -546
A3: 43191 | B3: 日
A4: 43192 | B4: 月 | F4: コーヒー | G4: -9
A5: 43193 | B5: 火 | L5: 髪 | M5: -25
A6: 43194 | B6: 水
A7: 43195 | B7: 木
A8: 43196 | B8: 金
A9: 43197 | B9: 土
A10: 43198 | B10: 日
A11: 43199 | B11: 月 | F11: コーヒー | G11: 10.5 | L11: コーヒー | M11: -21
A12: 43200 | B12: 火
A13: 43201 | B13: 水 | F13: コーヒー | G13: 11
F14: 昼ご飯 | G14: -27
A15: 43202 | B15: 木 | F15: コーヒー | G15: 11 | I15: 昼ご飯 | J15: 24
A16: 43203 | B16: 金 | F16: コーヒー | G16: -11
F17: 昼ご飯 | G17: 15
A18: 43204 | B18: 土
A19: 43205 | B19: 日
A20: 43206 | B20: 月 | F20: コーヒー | G20: 10.5
F21: 昼ご飯 | G21: 27
A22: 43207 | B22: 火 | F22: コーヒー | G22: 11
A23: 43208 | B23: 水 | F23: コーヒー | G23: 11 | L23: 現金受入 | M23: -500
F24: タクシー代 | G24: -23
A25: 43209 | B25: 木 | F25: コーヒー | G25: 11
A26: 43210 | B26: 金 | F26: コーヒー | G26: 11
A27: 43211 | B27: 土
A28: 43212 | B28: 日
A29: 43213 | B29: 月 | F29: コーヒー | G29: 10.5
A30: 43214 | B30: 火
A31: 43215 | B31: 水 | F31: コーヒー | G31: 11
A32: 43216 | B32: 木
A33: 43217 | B33: 金 | F33: 受入 | G33: -100 | I33: 受入 | J33: -100
A34: 43218 | B34: 土
A35: 43219 | B35: 日
A36: 43220 | B36: 月 | F36: コーヒー | G36: 10.5

Sheet 201803
C1: 楊 | F1: 張 | I1: 菜 | L1: 閻
A2: 日付 | B2: 曜日 | C2: =SUM(D3:D31) -> 0 | F2: =SUM(G3:G33) -> 34 | I2: =SUM(J3:J33) -> 57 | L2: =SUM(M3:M33) -> -6
A3: 43160 | B3: 木
A4: 43161 | B4: 金 | F4: 精算 | G4: -18
A5: 43162 | B5: 土
A6: 43163 | B6: 日
A7: 43164 | B7: 月
A8: 43165 | B8: 火
A9: 43166 | B9: 水
A10: 43167 | B10: 木
A11: 43168 | B11: 金
A12: 43169 | B12: 土
A13: 43170 | B13: 日
A14: 43171 | B14: 月
A15: 43172 | B15: 火
A16: 43173 | B16: 水
... A27: 43184 | B27: 日
A28: 43185 | B28: 月 | L28: ファミリー | M28: -6
A29: 43186 | B29: 火 | F29: コーヒー | G29: 11
A30: 43187 | B30: 水
A31: 43188 | B31: 木 | I31: 午後茶 | J31: 16
A32: 43189 | B32: 金 | F32: 昼ご飯 | G32: 41 | I32: 昼ご飯 | J32: 41
A33: 43190 | B33: 土

Sheet 201802
C1: 楊 | F1: 張 | I1: 菜 | L1: 閻
A2: 日付 | B2: 曜日 | C2: =SUM(D3:D31) -> 0 | F2: =SUM(G3:G31) -> 10 | I2: =SUM(J3:J31) -> 0 | L2: =SUM(M3:M31) -> -84
A3: 43132 | B3: 木
A4: 43133 | B4: 金
A5: 43134 | B5: 土
A6: 43135 | B6: 日
A7: 43136 | B7: 月
A8: 43137 | B8: 火
A9: 43138 | B9: 水 | F9: ファミリー | G9: 10 | L9: ファミリー | M9: -28
A10: 43139 | B10: 木
A11: 43140 | B11: 金 | L11: 鶏 | M11: 18
A12: 43141 | B12: 土
A13: 43142 | B13: 日
A14: 43143 | B14: 月
A15: 43144 | B15: 火
A16: 43145 | B16: 水 | L16: ファミリー | M16: 28
A17: 43146 | B17: 木
A18: 43147 | B18: 金
A19: 43148 | B19: 土
A20: 43149 | B20: 日
A21: 43150 | B21: 月
A22: 43151 | B22: 火
A23: 43152 | B23: 水 | L23: ファミリー | M23: 28
A24: 43153 | B24: 木 | L24: 木耳 | M24: -130
A25: 43154 | B25: 金
A26: 43155 | B26: 土
A27: 43156 | B27: 日
A28: 43157 | B28: 月
A29: 43158 | B29: 火
A30: 43159 | B30: 水

Sheet 201801
C1: 楊 | F1: 張 | I1: 菜 | L1: 閻
A2: 日付 | B2: 曜日 | C2: =SUM(D3:D35) -> 0 | F2: =SUM(G3:G35) -> 8 | I2: =SUM(J3:J35) -> -102 | L2: =SUM(M3:M35) -> -30
A3: 43101 | B3: 月
A4: 43102 | B4: 火 | F4: 昼ご飯 | G4: -22 | I4: 午後茶 | J4: 13
A5: 43103 | B5: 水 | I5: 午後茶 | J5: 6
A6: 43104 | B6: 木 | F6: タクシー代 | G6: 30 | I6: 午後茶 | J6: 15
A7: 43105 | B7: 金 | I7: 午後茶 | J7: 14
I8: 受入 | J8: -150
A9: 43106 | B9: 土
A10: 43107 | B10: 日
A11: 43108 | B11: 月
A12: 43109 | B12: 火
A13: 43110 | B13: 水
A14: 43111 | B14: 木
A15: 43112 | B15: 金
A16: 43113 | B16: 土
A17: 43114 | B17: 日
A18: 43115 | B18: 月
A19: 43116 | B19: 火
A20: 43117 | B20: 水
... A27: 43124 | B27: 水
A28: 43125 | B28: 木 | L28: ご飯 | M28: 13
A29: 43126 | B29: 金
A30: 43127 | B30: 土
A31: 43128 | B31: 日
A32: 43129 | B32: 月
A33: 43130 | B33: 火
A34: 43131 | B34: 水 | L34: 奢り | M34: -15
L35: ファミリー | M35: -28

Sheet 201712
C1: 楊 | F1: 張 | I1: 菜 | L1: 閻
A2: 日付 | B2: 曜日 | C2: =SUM(D3:D35) -> -151 | F2: =SUM(G3:G35) -> 33 | I2: =SUM(J3:J35) -> 0 | L2: =SUM(M3:M35) -> -56
A3: 43070 | B3: 金
A4: 43071 | B4: 土
A5: 43072 | B5: 日
A6: 43073 | B6: 月
A7: 43074 | B7: 火
A8: 43075 | B8: 水 | L8: ファミリー | M8: -28
A9: 43076 | B9: 木
A10: 43077 | B10: 金
A11: 43078 | B11: 土
A12: 43079 | B12: 日
A13: 43080 | B13: 月
A14: 43081 | B14: 火 | F14: 老盛 | G14: -26
F15: 取引 | G15: 59
A16: 43082 | B16: 水 | L16: ファミリー | M16: -28
A17: 43083 | B17: 木 | F17: 午後茶 | G17: 16
A18: 43084 | B18: 金 | C18: 精算 | D18: -151 | F18: 精算 | G18: -16
A19: 43085 | B19: 土
A20: 43086 | B20: 日
A21: 43087 | B21: 月
A22: 43088 | B22: 火
A23: 43089 | B23: 水
A24: 43090 | B24: 木
A25: 43091 | B25: 金
A26: 43092 | B26: 土
A27: 43093 | B27: 日
A28: 43094 | B28: 月
A29: 43095 | B29: 火
A30: 43096 | B30: 水
... A34: 43100 | B34: 日

Sheet 201711
C1: 楊 | F1: 張 | I1: 菜 | L1: 閻
A2: 日付 | B2: 曜日 | C2: =SUM(D3:D34) -> 0 | F2: =SUM(G3:G34) -> 0 | I2: =SUM(J3:J34) -> 0 | L2: =SUM(M3:M34) -> -140
A3: 43040 | B3: 水 | L3: ファミリー | M3: -28
A4: 43041 | B4: 木
A5: 43042 | B5: 金
A6: 43043 | B6: 土
A7: 43044 | B7: 日
A8: 43045 | B8: 月
A9: 43046 | B9: 火
A10: 43047 | B10: 水 | L10: ファミリー | M10: -28
A11: 43048 | B11: 木
A12: 43049 | B12: 金
A13: 43050 | B13: 土
A14: 43051 | B14: 日
A15: 43052 | B15: 月
A16: 43053 | B16: 火
A17: 43054 | B17: 水 | L17: ファミリー | M17: -28
A18: 43055 | B18: 木
A19: 43056 | B19: 金
A20: 43057 | B20: 土
A21: 43058 | B21: 日
A22: 43059 | B22: 月
A23: 43060 | B23: 火
A24: 43061 | B24: 水 | L24: ファミリー | M24: -28
A25: 43062 | B25: 木
A26: 43063 | B26: 金
A27: 43064 | B27: 土
A28: 43065 | B28: 日
A29: 43066 | B29: 月
A30: 43067 | B30: 火
A31: 43068 | B31: 水 | L31: ファミリー | M31: -28
A32: 43069 | B32: 木

Sheet 201710
C1: 楊 | F1: 張 | I1: 菜 | L1: 閻
A2: 日付 | B2: 曜日 | C2: =SUM(D3:D34) -> 0 | F2: =SUM(G3:G34) -> -981.2 | I2: =SUM(J3:J34) -> 0 | L2: =SUM(M3:M34) -> -314
A3: 43009 | B3: 日 | L3: 支払宝受入 | M3: -10
A4: 43010 | B4: 月 | L4: 支払宝受入 | M4: -10
A5: 43011 | B5: 火 | L5: 支払宝受入 | M5: -10
A6: 43012 | B6: 水 | L6: 支払宝受入 | M6: -20
A7: 43013 | B7: 木 | L7: 支払宝受入 | M7: -10
A8: 43014 | B8: 金 | F8: コーヒー | G8: 10 | L8: 支払宝受入 | M8: -40
F9: ファミリー | G9: 8.8
A10: 43015 | B10: 土
A11: 43016 | B11: 日 | L11: 支払宝受入 | M11: -10
A12: 43017 | B12: 月 | L12: 支払宝受入 | M12: -10
A13: 43018 | B13: 火
A14: 43019 | B14: 水 | L14: ファミリー | M14: -28
A15: 43020 | B15: 木
A16: 43021 | B16: 金
A17: 43022 | B17: 土 | L17: 支払宝受入 | M17: -50
A18: 43023 | B18: 日
A19: 43024 | B19: 月 | F19: 支払宝受入 | G19: -1000
A20: 43025 | B20: 火
A21: 43026 | B21: 水 | L21: ファミリー | M21: -28
A22: 43027 | B22: 木
A23: 43028 | B23: 金 | L23: 支払宝受入 | M23: -20
A24: 43029 | B24: 土
A25: 43030 | B25: 日
A26: 43031 | B26: 月
A27: 43032 | B27: 火
A28: 43033 | B28: 水 | L28: ファミリー | M28: -28
A29: 43034 | B29: 木
A30: 43035 | B30: 金 | L30: 支払宝受入 | M30: -40
A31: 43036 | B31: 土
A32: 43037 | B32: 日
A33: 43038 | B33: 月
A34: 43039 | B34: 火

Sheet 201709
C1: 楊 | F1: 張 | I1: 菜 | L1: 閻 | O1: 黄
A2: 日付 | B2: 曜日 | C2: =SUM(D3:D53) -> 117.7 | F2: =SUM(G3:G53) -> 948.3 | I2: =SUM(J3:J53) -> 24 | L2: =SUM(M3:M53) -> 47 | O2: =SUM(P3:P53) -> 0
A3: 42979 | B3: 金 | C3: 餃子 | D3: 12
A4: 42980 | B4: 土 | F4: 午後茶 | G4: 15.5
A5: 42981 | B5: 日
A6: 42982 | B6: 月 | C6: 鳥車 | D6: 7.5 | F6: コーヒー | G6: 6
A7: 42983 | B7: 火 | F7: 受入 | G7: -21.5
F8: コーヒー | G8: 10
A9: 42984 | B9: 水 | C9: 午後茶 | D9: 7 | F9: 午後茶 | G9: 13
A10: 42985 | B10: 木 | C10: 鳥車 | D10: 7 | F10: コーヒー | G10: 10
A11: 42986 | B11: 金 | F11: コーヒー | G11: 10
F12: 餃子 | G12: 12
A13: 42987 | B13: 土
A14: 42988 | B14: 日
A15: 42989 | B15: 月 | C15: 餃子 | D15: 13
C16: 午後茶 | D16: 14 | L16: 午後茶 | M16: 14
A17: 42990 | B17: 火 | C17: コーヒークーポン受入 | D17: -8 | F17: コーヒー | G17: 10
C18: 午後茶 | D18: 10
A19: 42991 | B19: 水 | C19: 午後茶 | D19: 14 | F19: 精算 | G19: 72
C20: 現金チャージ | D20: -100 | F20: 精算受入 | G20: -37
F21: 午後茶 | G21: 11
A22: 42992 | B22: 木 | F22: タクシー精算 | G22: 30
F23: 午後茶 | G23: 9
F24: 残業食事精算 | G24: 145.8
A25: 42993 | B25: 金 | C25: 餃子 | D25: 14 | F25: タクシー精算 | G25: 30
F26: 餃子 | G26: 14
A27: 42994 | B27: 土
A28: 42995 | B28: 日
A29: 42996 | B29: 月 | C29: KFCコーヒー | D29: 19
A30: 42997 | B30: 火 | C30: 午後茶 | D30: 7
A31: 42998 | B31: 水 | C31: 午後茶 | D31: 7 | F31: 残業食事精算 | G31: 129
A32: 42999 | B32: 木 | C32: 餃子 | D32: 13 | F32: 餃子 | G32: 13
C33: 午後茶 | D33: 8 | F33: 午後茶 | G33: 13
F34: 残業食事精算 | G34: 132
F35: タクシー精算 | G35: 26
A36: 43000 | B36: 金 | C36: 支払宝 | D36: 2
A37: 43001 | B37: 土 | F37: 残業食事精算 | G37: 111 | L37: 精算受入 | M37: -4
F38: 残業食事精算 | G38: 56
F39: 残業食事精算 | G39: 30
F40: 午後茶 | G40: 10
...

Sheet 201708
C1: 楊 | F1: 張 | I1: 菜 | L1: 閻
A2: 日付 | B2: 曜日 | C2: =SUM(D3:D37) -> -7.8 | F2: =SUM(G3:G37) -> -72 | I2: =SUM(J3:J37) -> 76 | L2: =SUM(M3:M37) -> 0
A3: 42948 | B3: 火 | D3: 15 | G3: 12
A4: 42949 | B4: 水
A5: 42950 | B5: 木 | G5: 14
A6: 42951 | B6: 金 | D6: 14 | G6: 14
A7: 42952 | B7: 土
A8: 42953 | B8: 日
A9: 42954 | B9: 月 | D9: 8
A10: 42955 | B10: 火 | D10: 8
A11: 42956 | B11: 水
A12: 42957 | B12: 木
A13: 42958 | B13: 金
A14: 42959 | B14: 土 | D14: =8-100 -> -92
A15: 42960 | B15: 日
A16: 42961 | B16: 月 | D16: 20 | G16: -100
A17: 42962 | B17: 火 | D17: 12 | G17: =30+14 -> 44 | J17: 30
A18: 42963 | B18: 水 | G18: =14-16 -> -2
A19: 42964 | B19: 木 | D19: 46 | G19: =12+46 -> 58 | J19: 46
A20: 42965 | B20: 金 | G20: 12
A21: 42966 | B21: 土
A22: 42967 | B22: 日
A23: 42968 | B23: 月
A24: 42969 | B24: 火
A25: 42970 | B25: 水 | C25: パン | D25: 8 | F25: コーヒー | G25: 12
A26: 42971 | B26: 木 | C26: とり | D26: 7.5 | F26: コーヒー | G26: 12
A27: 42972 | B27: 金 | C27: 支払宝 | D27: 8 | F27: コーヒー | G27: 12
A28: 42973 | B28: 土
A29: 42974 | B29: 日
A30: 42975 | B30: 月 | F30: コーヒー | G30: 9
F31: 受入 | G31: -170
A32: 42976 | B32: 火 | C32: 昼ご飯 | D32: 16 | F32: コーヒー | G32: 12
C33: 受入 | D33: -100 | F33: 受入 | G33: -11
C34: 午後茶 | D34: 7
A35: 42977 | B35: 水 | C35: 小楊 | D35: 10
C36: おでん | D36: 4.7
A37: 42978 | B37: 木

Sheet 报销
B2: 合计 | C2: =SUM(B:B)+SUM(J:J)+SUM(Q:Q) -> 0
C5: 加班餐 | K5: 出租车 | R5: 支付核销
C6: 状态 | D6: 填单日付 | E6: 报销日期 | F6: 金額 | G6: 人数 | H6: 備考 | K6: 状态 | L6: 填单日付 | M6: 报销日期 | N6: 金額 | O6: 備考 | R6: 状态 | S6: 日付 | T6: 金額 | U6: 備考
B7: =IF(C7="已填单",F7,0) -> 0 | C7: 已核销 | D7: 43172 | F7: 104 | G7: 4 | J7: =IF(K7="已填单",O7,0) -> 0 | K7: 已核销 | L7: 43185 | N7: 145 | O7: 張：23 黄：58 | Q7: =IF(R7="已填单",T7,0) -> 0 | R7: 已核销 | S7: 43642 | T7: 650 | U7: 签证
B8: =IF(C8="已填单",F8,0) -> 0 | C8: 已核销 | D8: 43175 | F8: 77 | G8: 3 | J8: =IF(K8="已填单",O8,0) -> 0 | K8: 已核销 | L8: 43287 | N8: 223
B9: =IF(C9="已填单",F9,0) -> 0 | C9: 已核销 | D9: 43176 | F9: 181 | G9: 6 | J9: =IF(K9="已填单",O9,0) -> 0 | K9: 已核销 | L9: 43495 | N9: 284
B10: =IF(C10="已填单",F10,0) -> 0 | C10: 已核销 | F10: 100 | G10: 4 | J10: =IF(K10="已填单",O10,0) -> 0 | K10: 已核销 | L10: 43498 | N10: 136 | O10: 張：24 黄：42
B11: =IF(C11="已填单",F11,0) -> 0 | C11: 已核销 | F11: 25.6 | G11: 1 | J11: =IF(K11="已填单",O11,0) -> 0 | K11: 已核销 | L11: 43514 | N11: 189 | O11: 張：92
B12: =IF(C12="已填单",F12,0) -> 0 | C12: 已核销 | D12: 43182 | F12: 98 | G12: 4 | H12: 周张黄菜 | J12: =IF(K12="已填单",O12,0) -> 0 | K12: 已核销 | L12: 43514 | N12: 141 | O12: 張：38 張子超：33
B13: =IF(C13="已填单",F13,0) -> 0 | C13: 已核销 | D13: 43232 | F13: 116 | G13: 4 | H13: 崔张范A | J13: =IF(K13="已填单",O13,0) -> 0 | K13: 已核销 | L13: 43532 | N13: 360 | O13: 朱磊：137 小明：84 黄伟：28+70
B14: =IF(C14="已填单",F14,0) -> 0 | C14: 已核销 | D14: 43234 | F14: =57+66 -> 123 | G14: 4 | H14: 崔张范A | J14: =IF(K14="已填单",O14,0) -> 0 | K14: 已核销 | L14: 43608 | N14: 153 | O14: 張：44
B15: =IF(C15="已填单",F15,0) -> 0 | C15: 已核销 | D15: 43241 | F15: 111.5 | G15: 6 | J15: =IF(K15="已填单",N15,0) -> 0 | K15: 已核销 | L15: 43615 | M15: 43644 | N15: 302 | O15: 張：62 李梅：29 陳：132
B16: =IF(C16="已填单",F16,0) -> 0 | C16: 已核销 | D16: 43256 | F16: 316 | J16: =IF(K16="已填单",N16,0) -> 0 | K16: 已核销 | L16: 43620 | M16: 43644 | N16: 302 | O16: 張：58 黄：67 宗：101
B17: =IF(C17="已填单",F17,0) -> 0 | C17: 已核销 | D17: 43277 | F17: 672 | J17: =IF(K17="已填单",N17,0) -> 0 | K17: 已核销 | L17: 43630 | M17: 43644 | N17: 134 | O17: 張：63
B18: =IF(C18="已填单",F18,0) -> 0 | C18: 已核销 | D18: 43288 | F18: 327 | J18: =IF(K18="已填单",N18,0) -> 0 | K18: 已核销 | L18: 43637 | M18: 43682 | N18: 145 | O18: 張：45
B19: =IF(C19="已填单",F19,0) -> 0 | C19: 已核销 | D19: 43357 | F19: 1202 | H19: 43389 | J19: =IF(K19="已填单",N19,0) -> 0 | K19: 已核销 | L19: 43682 | M19: 43704 | N19: 80
B20: =IF(C20="已填单",F20,0) -> 0 | C20: 已核销 | D20: 43357 | F20: 834 | J20: =IF(K20="已填单",N20,0) -> 0 | K20: 已核销 | L20: 43801 | M20: 43824 | N20: 281 | O20: 劉：113 黄：56+72
B21: =IF(C21="已填单",F21,0) -> 0 | C21: 已核销 | D21: 43363 | F21: 979 | J21: =IF(K21="已填单",N21,0) -> 0 | K21: 已核销 | L21: 43816 | M21: 43824 | N21: 31
B22: =IF(C22="已填单",F22,0) -> 0 | C22: 已核销 | D22: 43389 | F22: =144+33 -> 177 | H22: 刘晓丹
B23: =IF(C23="已填单",F23,0) -> 0 | C23: 已核销 | D23: 43404 | F23: 152
B24: =IF(C24="已填单",F24,0) -> 0 | C24: 已核销 | D24: 43404 | F24: 859.5 | H24: 43425
B25: =IF(C25="已填单",F25,0) -> 0 | C25: 已核销 | D25: 43423 | F25: 3139 | H25: ???
B26: =IF(C26="已填单",F26,0) -> 0 | C26: 已核销 | D26: 43433 | F26: 1080 | H26: 43486
B27: =IF(C27="已填单",F27,0) -> 0 | C27: 已核销 | D27: 43495 | F27: 2305
B28: =IF(C28="已填单",F28,0) -> 0 | C28: 已核销 | D28: 43505 | F28: 447.8 | H28: 黄：210-10 張子超：141
B29: =IF(C29="已填单",F29,0) -> 0 | C29: 已核销 | D29: 43595 | F29: 793.8 | H29: 吴：129 李梅：29.8
B30: =IF(C30="已填单",F30,0) -> 0 | C30: 已核销 | D30: 43615 | E30: 43644 | F30: 581 | H30: 朱：62
B31: =IF(C31="已填单",F31,0) -> 0 | C31: 已核销 | D31: 43615 | E31: 43644 | F31: 646 | H31: 張：109 李梅：76
B32: =IF(C32="已填单",F32,0) -> 0 | C32: 已核销 | D32: 43627 | E32: 43644 | F32: 627 | H32: 黄：90 李梅：180
B33: =IF(C33="已填单",F33,0) -> 0 | C33: 已核销 | D33: 43629 | E33: 43644 | F33: 1114 | H33: 張：506
B34: =IF(C34="已填单",F34,0) -> 0 | C34: 已核销 | D34: 43635 | E34: 43644 | F34: 727 | H34: 呉一凡：170
B35: =IF(C35="已填单",F35,0) -> 0 | C35: 已核销 | D35: 43643 | E35: 43682 | F35: 682.3 | H35: 張：26.3
B36: =IF(C36="已填单",F36,0) -> 0 | C36: 已核销 | D36: 43686 | E36: 43704 | F36: 1658 | H36: 張：29
B37: =IF(C37="已填单",F37,0) -> 0 | C37: 已核销 | D37: 43703 | F37: 483 | H37: 吴：30 徐磊：30
B38: =IF(C38="已填单",F38,0) -> 0 | C38: 已核销 | D38: 43790 | E38: 43824 | F38: 1008 | H38: 吴：92
B39: =IF(C39="已填单",F39,0) -> 0 | C39: 已核销 | D39: 43802 | E39: 43824 | F39: 1162.4 | H39: 劉：65
B40: =IF(C40="已填单",F40,0) -> 0 | C40: 已核销 | D40: 43802 | E40: 43824 | F40: 907.9 | H40: 劉：60 黄：381.9
B41: =IF(C41="已填单",F41,0) -> 0 | C41: 已核销 | D41: 43802 | E41: 43824 | F41: 826 | H41: 吴：255 徐：133 黄：236
B42: =IF(C42="已填单",F42,0) -> 0 | C42: 已核销 | D42: 43813 | E42: 43824 | F42: 1005.4 | H42: 朱：30+35 刘：513 黄：117.4 孙：32
B43: =IF(C43="已填单",F43,0) -> 0 | C43: 已核销 | D43: 43816 | E43: 43824 | F43: 28
...

Sheet 发票管理
B3: 开票日期 | C3: 金额 | D3: 校验码 | E3: 使用状况
B4: 43487 | C4: 141 | D4: 41253 | E4: 未使用
B5: 43519 | C5: 888 | D5: 27235 | E5: 已使用
B6: 43529 | C6: 18 | D6: 70048 | E6: 未使用
B7: 43531 | C7: 76.5 | D7: 39452 | E7: 已使用
B8: 43537 | C8: 60 | D8: 30016 | E8: 已使用
B9: 43537 | C9: 60 | D9: 80921 | E9: 已使用
B10: 43540 | C10: 1552 | D10: 14288 | E10: 已使用
B11: 43526 | C11: 64 | D11: 35209 | E11: 已使用
B12: 43550 | C12: 60 | D12: 24840 | E12: 已使用
B13: 43550 | C13: 60 | D13: 47712 | E13: 已使用
B14: 43551 | C14: 60 | D14: 71632 | E14: 未使用
B15: 43551 | C15: 60 | D15: 84333 | E15: 未使用
... B24: 43561 | C24: 80 | D24: 53309 | E24: 未使用
